Workbook

Sheet 考え方
B2: 計算クラスと、量クラスを区分する
C3: 例：テレビの買いかえ計算クラス － 消費量クラス（インスタンスはテレビ買い替えn台目）
B5: 設定値は計算クラスに設定
C6: 例：テレビの価格、テレビの性能等
B8: 対策計算では、なるべく「削減率」を通じて削減計算をする
B10: 1 | C10: 関数があればそれを選ぶ
B11: 2 | C11: 削減率の配列があればそれを選ぶ（Consで計算）
B12: 3 | C12: 設定値があればそれを選ぶ（ConsStrategy固定値）
A14: 消費量と対策を一括して計算をする
A15: 消費量は確定している状態で、対策の計算を一括で行う
A16: 分野の追加をする（追加をして、他の入力の追加も対応する）
A19: cons
B20: calc
B21: calcCO2
A22: measures
B23: calc
B24: calcCO2
B25: calcCO2Change
B26: dispDetail | D26: 対策ごとに、詳細について値を得ることができる
A31: PHPとActionscriptの両方に対応
B33: 消費量クラスでASかPHPかの記述を変更可能
B38: PHP
B40: AS
B41: PHP

Sheet readme
A1: Home Energy Diagnosis system language definition sheets
A3: use this sheets to magage parameters and translation
A4: please translate right color cell to left one. | D4: Fill cells of this color | E4: reference
A5: fill this sheet and copy "source code" cells to program code.
A7: sheet name | B7: target | C7: source code to paste
A8: Field | B8: "Field Name" and "Input field name" | C8: not use
A9: Items | B9: fill "Language set" | C9: d6/logic_**/senarofix.js
A10: Measures | B10: title, title short, easyness, subsidy, advice, | C10: d6/logic_**/senaroset.js
A11: Input | B11: title, unit, text, Input type, display value, save data | C11: d6/logic_**/senaroset.js
A12: Language | B12: fill "Language set" | C12: language/lang_**.php
A14: Area | B14: Place/Area, average templature(summer, winter) | C14: d6/logic_**/senaroset.js manual setting
A17: ver 2.1 | B17: create this readme sheet | C17: 43056
B18: Measures:change name hojoGov to subsidy
B19: Input: insert action valuation parameters
B20: Input: insert action valuation questions
B21: Items: add season
B22: Language: countfix_pre_after
A24: Ver3.0 | B24: not use js Language set combined to PHP | C24: 43058
B26: other misspelling | C26: 43064
B27: use Equipment list | C27: 44534

Sheet Field
A1: Field Code | F1: Fill cells of this color
B3: ID | C3: Field name | D3: Input field name | E3: code | F3: reference name | G3: reference input
B4: 0 | C4: 太陽光・契約 | D4: 家庭全般 | E4: TO | F4: 太陽光・契約 | G4: 家庭全般
B5: 1 | C5: 給湯・水道 | D5: 給湯・水道 | E5: HW | F5: 給湯・水道 | G5: 給湯・水道
B6: 2 | C6: 冷暖房 | D6: 冷暖房 | E6: AC | F6: 冷暖房 | G6: 冷暖房
B7: 3 | C7: 調理 | E7: CK | F7: 調理
B8: 4 | C8: 洗濯・衣類乾燥 | D8: 洗濯・乾燥 | E8: DR | F8: 洗濯・衣類乾燥 | G8: 洗濯・乾燥
B9: 5 | C9: 照明 | D9: 照明 | E9: LI | F9: 照明 | G9: 照明
B10: 6 | C10: テレビ | D10: テレビ・オーディオ | E10: TV | F10: テレビ | G10: テレビ・オーディオ
B11: 7 | C11: 冷蔵庫 | D11: 冷蔵庫 | E11: RF | F11: 冷蔵庫 | G11: 冷蔵庫
B12: 8 | C12: 自家用車 | E12: CR | F12: 自家用車
B13: 9 | C13: 待機電力・その他 | E13: OT | F13: 待機電力・その他
C14: 暖房 | D14: 暖房 | E14: HT | F14: 暖房 | G14: 暖房
C15: 冷房 | D15: 冷房 | E15: CO | F15: 冷房 | G15: 冷房
A17: Input Code | C17: range 100 is field ID | E17: ex. | F17: In100
A20: measure Code
C21: code name is "m" + fieldcode + name | E21: ex. | F21: mLIExchange

Sheet クラス
A1: Diagnosis
B2: 全てのクラス実体の保持。計算実行。
B4: Diagnosis | C4: コンストラクタ
B5: setSenario | C5: 初期構造設定 | D5: 消費量計算クラスの実装
D6: 消費量クラスの実装
D7: 消費量クラスの関連構造設定
D8: 対策クラスの実装（addMeasureAllCons）
D9: 入力変数の展開
D10: 質問リストの作成
B13: addMeasureAllCons | C13: 対策クラスの実装 | D13: addMeasureOneConsを複数回呼び出す
B16: addMeasureOneCons | C16: 対策１個の追加
B18: addCons | C18: 分野の追加 | D18: 消費量クラスの実装
D19: 消費量クラスの関連構造設定
D20: addMeasureOneConsを呼び出して対策を追加する
D21: 変数の追加
B23: calcConsAdjust | C23: 消費量計算の整合性 | D23: 補正率の算出
D24: cons::calcAdjustの呼び出し
B26: calcCons | C26: 消費量計算 | D26: 世帯人数・地域設定
D27: 初期計算
D28: 分野間関連計算
D29: 消費量計算の整合性（calcConsAdjust)
D30: 価格計算
B33: calcMeasures | C33: 対策自動計算 | D33: 選択状態の保存
D34: 選択状態のクリア
D35: １つずつ追加しての計算 cons.addReduction()
D36: 選択条件を戻す
B38: calcMeasuresLifestyle | C38: ライフスタイル対策のみ自動計算
B40: calcMeasuresOne | C40: 現状の対策計算 | D40: 現状状態で１回だけ計算をする
B42: measureAdd | C42: 対策選択を追加 | D42: フラグの設定
D43: calcMeasuresOneの実行
B45: measureDelete | C45: 対策選択を削除 | D45: フラグの設定
D46: 積み上げ直しcalcMeasuresの実行
B48: clearSelectedMeasures | C48: 全対策を削除 | D48: フラグをすべて解除
D49: calcMeasuresOneの実行
B51: rankIn100 | C51: 100世帯中順位 | D51: 順位計算
A54: Cons extended Energy
B55: 消費量値の実体、計算指示はこの実体に対して行われるが、計算は計算クラスに渡される。
B56: diagnosisクラスに配列として保持されている
B58: energy | D58: エネルギー種別の消費量
B59: value | D59: 対策計算等で使われる変数の保持
...

Sheet 消費量クラス
A1: 消費量クラス一覧（ソースコードで設定） | G1: ※addMeasureで変更があったら伝える先 | P1: 消費計算クラス実装AS | R1: AS | S1: 消費クラス定義 | X1: AS { par1:data1, par2:data2…..} PHP ( para1=>data1, para2=>data2…..)
B2: ID | C2: クラス名 | D2: 短縮名 | E2: タイトル | F2: 初期実装数 0は増加できない | G2: 集約クラス1 | H2: 関連クラス2 | I2: 代替使用クラス | J2: 分野CODE | K2: 色 | L2: 簡素レベル | R2: 上記をASにするとActionScript それ以外はPHP | U2: 不要
C3: name | D3: nameCode | E3: title | F3: count | G3: sumClass | H3: refClass | I3: substituteClass | J3: code | K3: color | L3: level
B4: 0 | C4: consTotal | D4: TO | E4: 全体 | F4: 0 | J4: 0 | K4: 0xa9a9a9 | L4: 1 | R4: =IF($R$1="AS","consCalcList['","$consCalcList['")&C4&IF($R$1="AS","'] = new logic.C","'] = new C")&MID(C4,2,20)&"();" -> consCalcList['consTotal'] = new logic.ConsTotal(); | U4: =IF($R$1="AS","defCons['"&C4&"'] = { "&C$3&":'"&C4&"', "&D$3&": '"&D4&"', "&E$3&":'"&E4&"', "&F$3&":"&F4&", "&G$3&":'"&G4&"', "&H$3&":'"&H4&"', "&I$3&":'"&I4&"', "&J$3&":"&J4&", "&K$3&":'"&K4&"' };","$this->defCons['"&C4&"'] = [ '"&C4&"', '"&D4&"', '"&E4&"', "&F4&", '"&G4&"', '"&H4&"', '"&I4&"', "&J4&", '"&K4&"' ];") -> defCons['consTotal'] = { name:'consTotal', nameCode: 'TO', title:'全体', count:0, sumClass:'', refClass:'', substituteClass:'', code:0, color:'0xa9a9a9' };
B5: 1 | C5: consHWsum | D5: HW | E5: 給湯・水道 | F5: 0 | G5: consTotal | J5: 1 | K5: 0xffb700 | L5: 1 | R5: =IF($R$1="AS","consCalcList['","$consCalcList['")&C5&IF($R$1="AS","'] = new logic.C","'] = new C")&MID(C5,2,20)&"();" -> consCalcList['consHWsum'] = new logic.ConsHWsum(); | U5: =IF($R$1="AS","defCons['"&C5&"'] = { "&C$3&":'"&C5&"', "&D$3&": '"&D5&"', "&E$3&":'"&E5&"', "&F$3&":"&F5&", "&G$3&":'"&G5&"', "&H$3&":'"&H5&"', "&I$3&":'"&I5&"', "&J$3&":"&J5&", "&K$3&":'"&K5&"' };","$this->defCons['"&C5&"'] = [ '"&C5&"', '"&D5&"', '"&E5&"', "&F5&", '"&G5&"', '"&H5&"', '"&I5&"', "&J5&", '"&K5&"' ];") -> defCons['consHWsum'] = { name:'consHWsum', nameCode: 'HW', title:'給湯・水道', count:0, sumClass:'consTotal', refClass:'', substituteClass:'', code:1, color:'0xffb700' };
B6: 2 | C6: consHWtub | E6: 浴槽 | F6: 0 | G6: consHWsum | H6: consHWshower | J6: 1 | L6: 2 | R6: =IF($R$1="AS","consCalcList['","$consCalcList['")&C6&IF($R$1="AS","'] = new logic.C","'] = new C")&MID(C6,2,20)&"();" -> consCalcList['consHWtub'] = new logic.ConsHWtub(); | U6: =IF($R$1="AS","defCons['"&C6&"'] = { "&C$3&":'"&C6&"', "&D$3&": '"&D6&"', "&E$3&":'"&E6&"', "&F$3&":"&F6&", "&G$3&":'"&G6&"', "&H$3&":'"&H6&"', "&I$3&":'"&I6&"', "&J$3&":"&J6&", "&K$3&":'"&K6&"' };","$this->defCons['"&C6&"'] = [ '"&C6&"', '"&D6&"', '"&E6&"', "&F6&", '"&G6&"', '"&H6&"', '"&I6&"', "&J6&", '"&K6&"' ];") -> defCons['consHWtub'] = { name:'consHWtub', nameCode: '', title:'浴槽', count:0, sumClass:'consHWsum', refClass:'consHWshower', substituteClass:'', code:1, color:'' };
B7: 3 | C7: consHWshower | E7: シャワー | F7: 0 | G7: consHWsum | J7: 1 | L7: 2 | R7: =IF($R$1="AS","consCalcList['","$consCalcList['")&C7&IF($R$1="AS","'] = new logic.C","'] = new C")&MID(C7,2,20)&"();" -> consCalcList['consHWshower'] = new logic.ConsHWshower(); | U7: =IF($R$1="AS","defCons['"&C7&"'] = { "&C$3&":'"&C7&"', "&D$3&": '"&D7&"', "&E$3&":'"&E7&"', "&F$3&":"&F7&", "&G$3&":'"&G7&"', "&H$3&":'"&H7&"', "&I$3&":'"&I7&"', "&J$3&":"&J7&", "&K$3&":'"&K7&"' };","$this->defCons['"&C7&"'] = [ '"&C7&"', '"&D7&"', '"&E7&"', "&F7&", '"&G7&"', '"&H7&"', '"&I7&"', "&J7&", '"&K7&"' ];") -> defCons['consHWshower'] = { name:'consHWshower', nameCode: '', title:'シャワー', count:0, sumClass:'consHWsum', refClass:'', substituteClass:'', code:1, color:'' };
B8: 15 | C8: consHWdishwash | E8: 食洗 | F8: 0 | G8: consHWsum | J8: 1 | L8: 2 | R8: =IF($R$1="AS","consCalcList['","$consCalcList['")&C8&IF($R$1="AS","'] = new logic.C","'] = new C")&MID(C8,2,20)&"();" -> consCalcList['consHWdishwash'] = new logic.ConsHWdishwash(); | U8: =IF($R$1="AS","defCons['"&C8&"'] = { "&C$3&":'"&C8&"', "&D$3&": '"&D8&"', "&E$3&":'"&E8&"', "&F$3&":"&F8&", "&G$3&":'"&G8&"', "&H$3&":'"&H8&"', "&I$3&":'"&I8&"', "&J$3&":"&J8&", "&K$3&":'"&K8&"' };","$this->defCons['"&C8&"'] = [ '"&C8&"', '"&D8&"', '"&E8&"', "&F8&", '"&G8&"', '"&H8&"', '"&I8&"', "&J8&", '"&K8&"' ];") -> defCons['consHWdishwash'] = { name:'consHWdishwash', nameCode: '', title:'食洗', count:0, sumClass:'consHWsum', refClass:'', substituteClass:'', code:1, color:'' };
B9: 4 | C9: consHWdresser | E9: 洗面 | F9: 0 | G9: consHWsum | J9: 1 | L9: 3 | R9: =IF($R$1="AS","consCalcList['","$consCalcList['")&C9&IF($R$1="AS","'] = new logic.C","'] = new C")&MID(C9,2,20)&"();" -> consCalcList['consHWdresser'] = new logic.ConsHWdresser(); | U9: =IF($R$1="AS","defCons['"&C9&"'] = { "&C$3&":'"&C9&"', "&D$3&": '"&D9&"', "&E$3&":'"&E9&"', "&F$3&":"&F9&", "&G$3&":'"&G9&"', "&H$3&":'"&H9&"', "&I$3&":'"&I9&"', "&J$3&":"&J9&", "&K$3&":'"&K9&"' };","$this->defCons['"&C9&"'] = [ '"&C9&"', '"&D9&"', '"&E9&"', "&F9&", '"&G9&"', '"&H9&"', '"&I9&"', "&J9&", '"&K9&"' ];") -> defCons['consHWdresser'] = { name:'consHWdresser', nameCode: '', title:'洗面', count:0, sumClass:'consHWsum', refClass:'', substituteClass:'', code:1, color:'' };
B10: 5 | C10: consHWtoilet | E10: トイレ | F10: 0 | G10: consHWsum | J10: 1 | L10: 3 | R10: =IF($R$1="AS","consCalcList['","$consCalcList['")&C10&IF($R$1="AS","'] = new logic.C","'] = new C")&MID(C10,2,20)&"();" -> consCalcList['consHWtoilet'] = new logic.ConsHWtoilet(); | U10: =IF($R$1="AS","defCons['"&C10&"'] = { "&C$3&":'"&C10&"', "&D$3&": '"&D10&"', "&E$3&":'"&E10&"', "&F$3&":"&F10&", "&G$3&":'"&G10&"', "&H$3&":'"&H10&"', "&I$3&":'"&I10&"', "&J$3&":"&J10&", "&K$3&":'"&K10&"' };","$this->defCons['"&C10&"'] = [ '"&C10&"', '"&D10&"', '"&E10&"', "&F10&", '"&G10&"', '"&H10&"', '"&I10&"', "&J10&", '"&K10&"' ];") -> defCons['consHWtoilet'] = { name:'consHWtoilet', nameCode: '', title:'トイレ', count:0, sumClass:'consHWsum', refClass:'', substituteClass:'', code:1, color:'' };
B11: 6 | C11: consHTsum | D11: HT | E11: 暖房 | F11: 0 | G11: consTotal | H11: consHW | J11: 2 | K11: 0xff0000 | L11: 1 | M11: ※床温水暖房など | R11: =IF($R$1="AS","consCalcList['","$consCalcList['")&C11&IF($R$1="AS","'] = new logic.C","'] = new C")&MID(C11,2,20)&"();" -> consCalcList['consHTsum'] = new logic.ConsHTsum(); | U11: =IF($R$1="AS","defCons['"&C11&"'] = { "&C$3&":'"&C11&"', "&D$3&": '"&D11&"', "&E$3&":'"&E11&"', "&F$3&":"&F11&", "&G$3&":'"&G11&"', "&H$3&":'"&H11&"', "&I$3&":'"&I11&"', "&J$3&":"&J11&", "&K$3&":'"&K11&"' };","$this->defCons['"&C11&"'] = [ '"&C11&"', '"&D11&"', '"&E11&"', "&F11&", '"&G11&"', '"&H11&"', '"&I11&"', "&J11&", '"&K11&"' ];") -> defCons['consHTsum'] = { name:'consHTsum', nameCode: 'HT', title:'暖房', count:0, sumClass:'consTotal', refClass:'consHW', substituteClass:'', code:2, color:'0xff0000' };
B12: 7 | C12: consCOsum | D12: CO | E12: 冷房除湿 | F12: 0 | G12: consTotal | J12: 2 | K12: 0x0000ff | L12: 1 | R12: =IF($R$1="AS","consCalcList['","$consCalcList['")&C12&IF($R$1="AS","'] = new logic.C","'] = new C")&MID(C12,2,20)&"();" -> consCalcList['consCOsum'] = new logic.ConsCOsum(); | U12: =IF($R$1="AS","defCons['"&C12&"'] = { "&C$3&":'"&C12&"', "&D$3&": '"&D12&"', "&E$3&":'"&E12&"', "&F$3&":"&F12&", "&G$3&":'"&G12&"', "&H$3&":'"&H12&"', "&I$3&":'"&I12&"', "&J$3&":"&J12&", "&K$3&":'"&K12&"' };","$this->defCons['"&C12&"'] = [ '"&C12&"', '"&D12&"', '"&E12&"', "&F12&", '"&G12&"', '"&H12&"', '"&I12&"', "&J12&", '"&K12&"' ];") -> defCons['consCOsum'] = { name:'consCOsum', nameCode: 'CO', title:'冷房除湿', count:0, sumClass:'consTotal', refClass:'', substituteClass:'', code:2, color:'0x0000ff' };
B13: 8 | C13: consAC | E13: 個別冷暖房 | F13: 3 | J13: 2 | L13: 3 | R13: =IF($R$1="AS","consCalcList['","$consCalcList['")&C13&IF($R$1="AS","'] = new logic.C","'] = new C")&MID(C13,2,20)&"();" -> consCalcList['consAC'] = new logic.ConsAC(); | U13: =IF($R$1="AS","defCons['"&C13&"'] = { "&C$3&":'"&C13&"', "&D$3&": '"&D13&"', "&E$3&":'"&E13&"', "&F$3&":"&F13&", "&G$3&":'"&G13&"', "&H$3&":'"&H13&"', "&I$3&":'"&I13&"', "&J$3&":"&J13&", "&K$3&":'"&K13&"' };","$this->defCons['"&C13&"'] = [ '"&C13&"', '"&D13&"', '"&E13&"', "&F13&", '"&G13&"', '"&H13&"', '"&I13&"', "&J13&", '"&K13&"' ];") -> defCons['consAC'] = { name:'consAC', nameCode: '', title:'個別冷暖房', count:3, sumClass:'', refClass:'', substituteClass:'', code:2, color:'' };
B14: 9 | C14: consACheat | E14: 個別暖房 | F14: 3 | G14: consHTsum | H14: consAC | J14: 2 | L14: 2 | R14: =IF($R$1="AS","consCalcList['","$consCalcList['")&C14&IF($R$1="AS","'] = new logic.C","'] = new C")&MID(C14,2,20)&"();" -> consCalcList['consACheat'] = new logic.ConsACheat(); | U14: =IF($R$1="AS","defCons['"&C14&"'] = { "&C$3&":'"&C14&"', "&D$3&": '"&D14&"', "&E$3&":'"&E14&"', "&F$3&":"&F14&", "&G$3&":'"&G14&"', "&H$3&":'"&H14&"', "&I$3&":'"&I14&"', "&J$3&":"&J14&", "&K$3&":'"&K14&"' };","$this->defCons['"&C14&"'] = [ '"&C14&"', '"&D14&"', '"&E14&"', "&F14&", '"&G14&"', '"&H14&"', '"&I14&"', "&J14&", '"&K14&"' ];") -> defCons['consACheat'] = { name:'consACheat', nameCode: '', title:'個別暖房', count:3, sumClass:'consHTsum', refClass:'consAC', substituteClass:'', code:2, color:'' };
B15: 10 | C15: consACcool | E15: 個別冷房 | F15: 3 | G15: consCOsum | H15: consAC | J15: 2 | L15: 2 | R15: =IF($R$1="AS","consCalcList['","$consCalcList['")&C15&IF($R$1="AS","'] = new logic.C","'] = new C")&MID(C15,2,20)&"();" -> consCalcList['consACcool'] = new logic.ConsACcool(); | U15: =IF($R$1="AS","defCons['"&C15&"'] = { "&C$3&":'"&C15&"', "&D$3&": '"&D15&"', "&E$3&":'"&E15&"', "&F$3&":"&F15&", "&G$3&":'"&G15&"', "&H$3&":'"&H15&"', "&I$3&":'"&I15&"', "&J$3&":"&J15&", "&K$3&":'"&K15&"' };","$this->defCons['"&C15&"'] = [ '"&C15&"', '"&D15&"', '"&E15&"', "&F15&", '"&G15&"', '"&H15&"', '"&I15&"', "&J15&", '"&K15&"' ];") -> defCons['consACcool'] = { name:'consACcool', nameCode: '', title:'個別冷房', count:3, sumClass:'consCOsum', refClass:'consAC', substituteClass:'', code:2, color:'' };
B16: 11 | C16: consRFsum | D16: RF | E16: 冷蔵庫 | F16: 0 | G16: consTotal | I16: consSum | J16: 3 | K16: 0x80ff80 | L16: 1 | R16: =IF($R$1="AS","consCalcList['","$consCalcList['")&C16&IF($R$1="AS","'] = new logic.C","'] = new C")&MID(C16,2,20)&"();" -> consCalcList['consRFsum'] = new logic.ConsRFsum(); | U16: =IF($R$1="AS","defCons['"&C16&"'] = { "&C$3&":'"&C16&"', "&D$3&": '"&D16&"', "&E$3&":'"&E16&"', "&F$3&":"&F16&", "&G$3&":'"&G16&"', "&H$3&":'"&H16&"', "&I$3&":'"&I16&"', "&J$3&":"&J16&", "&K$3&":'"&K16&"' };","$this->defCons['"&C16&"'] = [ '"&C16&"', '"&D16&"', '"&E16&"', "&F16&", '"&G16&"', '"&H16&"', '"&I16&"', "&J16&", '"&K16&"' ];") -> defCons['consRFsum'] = { name:'consRFsum', nameCode: 'RF', title:'冷蔵庫', count:0, sumClass:'consTotal', refClass:'', substituteClass:'consSum', code:3, color:'0x80ff80' };
B17: 12 | C17: consRF | E17: 冷蔵庫 | F17: 2 | G17: consRFsum | J17: 3 | L17: 2 | R17: =IF($R$1="AS","consCalcList['","$consCalcList['")&C17&IF($R$1="AS","'] = new logic.C","'] = new C")&MID(C17,2,20)&"();" -> consCalcList['consRF'] = new logic.ConsRF(); | U17: =IF($R$1="AS","defCons['"&C17&"'] = { "&C$3&":'"&C17&"', "&D$3&": '"&D17&"', "&E$3&":'"&E17&"', "&F$3&":"&F17&", "&G$3&":'"&G17&"', "&H$3&":'"&H17&"', "&I$3&":'"&I17&"', "&J$3&":"&J17&", "&K$3&":'"&K17&"' };","$this->defCons['"&C17&"'] = [ '"&C17&"', '"&D17&"', '"&E17&"', "&F17&", '"&G17&"', '"&H17&"', '"&I17&"', "&J17&", '"&K17&"' ];") -> defCons['consRF'] = { name:'consRF', nameCode: '', title:'冷蔵庫', count:2, sumClass:'consRFsum', refClass:'', substituteClass:'', code:3, color:'' };
B18: 13 | C18: consCKsum | D18: CK | E18: 調理 | F18: 0 | G18: consTotal | I18: consSum | J18: 4 | K18: 0xffe4b5 | L18: 1 | R18: =IF($R$1="AS","consCalcList['","$consCalcList['")&C18&IF($R$1="AS","'] = new logic.C","'] = new C")&MID(C18,2,20)&"();" -> consCalcList['consCKsum'] = new logic.ConsCKsum(); | U18: =IF($R$1="AS","defCons['"&C18&"'] = { "&C$3&":'"&C18&"', "&D$3&": '"&D18&"', "&E$3&":'"&E18&"', "&F$3&":"&F18&", "&G$3&":'"&G18&"', "&H$3&":'"&H18&"', "&I$3&":'"&I18&"', "&J$3&":"&J18&", "&K$3&":'"&K18&"' };","$this->defCons['"&C18&"'] = [ '"&C18&"', '"&D18&"', '"&E18&"', "&F18&", '"&G18&"', '"&H18&"', '"&I18&"', "&J18&", '"&K18&"' ];") -> defCons['consCKsum'] = { name:'consCKsum', nameCode: 'CK', title:'調理', count:0, sumClass:'consTotal', refClass:'', substituteClass:'consSum', code:4, color:'0xffe4b5' };
B19: 14 | C19: consCKcook | E19: 調理 | F19: 0 | G19: consCKsum | J19: 4 | L19: 3 | R19: =IF($R$1="AS","consCalcList['","$consCalcList['")&C19&IF($R$1="AS","'] = new logic.C","'] = new C")&MID(C19,2,20)&"();" -> consCalcList['consCKcook'] = new logic.ConsCKcook(); | U19: =IF($R$1="AS","defCons['"&C19&"'] = { "&C$3&":'"&C19&"', "&D$3&": '"&D19&"', "&E$3&":'"&E19&"', "&F$3&":"&F19&", "&G$3&":'"&G19&"', "&H$3&":'"&H19&"', "&I$3&":'"&I19&"', "&J$3&":"&J19&", "&K$3&":'"&K19&"' };","$this->defCons['"&C19&"'] = [ '"&C19&"', '"&D19&"', '"&E19&"', "&F19&", '"&G19&"', '"&H19&"', '"&I19&"', "&J19&", '"&K19&"' ];") -> defCons['consCKcook'] = { name:'consCKcook', nameCode: '', title:'調理', count:0, sumClass:'consCKsum', refClass:'', substituteClass:'', code:4, color:'' };
B20: 16 | C20: consCKplug | E20: 待機 | F20: 0 | G20: consCKsum | J20: 4 | L20: 3 | R20: =IF($R$1="AS","consCalcList['","$consCalcList['")&C20&IF($R$1="AS","'] = new logic.C","'] = new C")&MID(C20,2,20)&"();" -> consCalcList['consCKplug'] = new logic.ConsCKplug(); | U20: =IF($R$1="AS","defCons['"&C20&"'] = { "&C$3&":'"&C20&"', "&D$3&": '"&D20&"', "&E$3&":'"&E20&"', "&F$3&":"&F20&", "&G$3&":'"&G20&"', "&H$3&":'"&H20&"', "&I$3&":'"&I20&"', "&J$3&":"&J20&", "&K$3&":'"&K20&"' };","$this->defCons['"&C20&"'] = [ '"&C20&"', '"&D20&"', '"&E20&"', "&F20&", '"&G20&"', '"&H20&"', '"&I20&"', "&J20&", '"&K20&"' ];") -> defCons['consCKplug'] = { name:'consCKplug', nameCode: '', title:'待機', count:0, sumClass:'consCKsum', refClass:'', substituteClass:'', code:4, color:'' };
B21: 17 | C21: consCKpot | E21: ポット | F21: 0 | G21: consCKsum | J21: 4 | L21: 3 | R21: =IF($R$1="AS","consCalcList['","$consCalcList['")&C21&IF($R$1="AS","'] = new logic.C","'] = new C")&MID(C21,2,20)&"();" -> consCalcList['consCKpot'] = new logic.ConsCKpot(); | U21: =IF($R$1="AS","defCons['"&C21&"'] = { "&C$3&":'"&C21&"', "&D$3&": '"&D21&"', "&E$3&":'"&E21&"', "&F$3&":"&F21&", "&G$3&":'"&G21&"', "&H$3&":'"&H21&"', "&I$3&":'"&I21&"', "&J$3&":"&J21&", "&K$3&":'"&K21&"' };","$this->defCons['"&C21&"'] = [ '"&C21&"', '"&D21&"', '"&E21&"', "&F21&", '"&G21&"', '"&H21&"', '"&I21&"', "&J21&", '"&K21&"' ];") -> defCons['consCKpot'] = { name:'consCKpot', nameCode: '', title:'ポット', count:0, sumClass:'consCKsum', refClass:'', substituteClass:'', code:4, color:'' };
B22: 18 | C22: consCKrice | E22: 炊飯ジャー | F22: 0 | G22: consCKsum | J22: 4 | L22: 3 | R22: =IF($R$1="AS","consCalcList['","$consCalcList['")&C22&IF($R$1="AS","'] = new logic.C","'] = new C")&MID(C22,2,20)&"();" -> consCalcList['consCKrice'] = new logic.ConsCKrice(); | U22: =IF($R$1="AS","defCons['"&C22&"'] = { "&C$3&":'"&C22&"', "&D$3&": '"&D22&"', "&E$3&":'"&E22&"', "&F$3&":"&F22&", "&G$3&":'"&G22&"', "&H$3&":'"&H22&"', "&I$3&":'"&I22&"', "&J$3&":"&J22&", "&K$3&":'"&K22&"' };","$this->defCons['"&C22&"'] = [ '"&C22&"', '"&D22&"', '"&E22&"', "&F22&", '"&G22&"', '"&H22&"', '"&I22&"', "&J22&", '"&K22&"' ];") -> defCons['consCKrice'] = { name:'consCKrice', nameCode: '', title:'炊飯ジャー', count:0, sumClass:'consCKsum', refClass:'', substituteClass:'', code:4, color:'' };
B23: 19 | C23: consDRsum | D23: DR | E23: 洗濯乾燥 | F23: 0 | G23: consTotal | J23: 5 | K23: 0x00ffff | L23: 1 | R23: =IF($R$1="AS","consCalcList['","$consCalcList['")&C23&IF($R$1="AS","'] = new logic.C","'] = new C")&MID(C23,2,20)&"();" -> consCalcList['consDRsum'] = new logic.ConsDRsum(); | U23: =IF($R$1="AS","defCons['"&C23&"'] = { "&C$3&":'"&C23&"', "&D$3&": '"&D23&"', "&E$3&":'"&E23&"', "&F$3&":"&F23&", "&G$3&":'"&G23&"', "&H$3&":'"&H23&"', "&I$3&":'"&I23&"', "&J$3&":"&J23&", "&K$3&":'"&K23&"' };","$this->defCons['"&C23&"'] = [ '"&C23&"', '"&D23&"', '"&E23&"', "&F23&", '"&G23&"', '"&H23&"', '"&I23&"', "&J23&", '"&K23&"' ];") -> defCons['consDRsum'] = { name:'consDRsum', nameCode: 'DR', title:'洗濯乾燥', count:0, sumClass:'consTotal', refClass:'', substituteClass:'', code:5, color:'0x00ffff' };
B24: 20 | C24: consDRwash | E24: 洗濯 | F24: 0 | G24: consDRsum | J24: 5 | L24: 3 | R24: =IF($R$1="AS","consCalcList['","$consCalcList['")&C24&IF($R$1="AS","'] = new logic.C","'] = new C")&MID(C24,2,20)&"();" -> consCalcList['consDRwash'] = new logic.ConsDRwash(); | U24: =IF($R$1="AS","defCons['"&C24&"'] = { "&C$3&":'"&C24&"', "&D$3&": '"&D24&"', "&E$3&":'"&E24&"', "&F$3&":"&F24&", "&G$3&":'"&G24&"', "&H$3&":'"&H24&"', "&I$3&":'"&I24&"', "&J$3&":"&J24&", "&K$3&":'"&K24&"' };","$this->defCons['"&C24&"'] = [ '"&C24&"', '"&D24&"', '"&E24&"', "&F24&", '"&G24&"', '"&H24&"', '"&I24&"', "&J24&", '"&K24&"' ];") -> defCons['consDRwash'] = { name:'consDRwash', nameCode: '', title:'洗濯', count:0, sumClass:'consDRsum', refClass:'', substituteClass:'', code:5, color:'' };
B25: 21 | C25: consDRdry | E25: 乾燥 | F25: 0 | G25: consDRsum | J25: 5 | L25: 3 | R25: =IF($R$1="AS","consCalcList['","$consCalcList['")&C25&IF($R$1="AS","'] = new logic.C","'] = new C")&MID(C25,2,20)&"();" -> consCalcList['consDRdry'] = new logic.ConsDRdry(); | U25: =IF($R$1="AS","defCons['"&C25&"'] = { "&C$3&":'"&C25&"', "&D$3&": '"&D25&"', "&E$3&":'"&E25&"', "&F$3&":"&F25&", "&G$3&":'"&G25&"', "&H$3&":'"&H25&"', "&I$3&":'"&I25&"', "&J$3&":"&J25&", "&K$3&":'"&K25&"' };","$this->defCons['"&C25&"'] = [ '"&C25&"', '"&D25&"', '"&E25&"', "&F25&", '"&G25&"', '"&H25&"', '"&I25&"', "&J25&", '"&K25&"' ];") -> defCons['consDRdry'] = { name:'consDRdry', nameCode: '', title:'乾燥', count:0, sumClass:'consDRsum', refClass:'', substituteClass:'', code:5, color:'' };
B26: 22 | C26: consLIsum | D26: LI | E26: 照明 | F26: 0 | G26: consTotal | I26: consSum | J26: 6 | K26: 0xffff00 | L26: 1 | R26: =IF($R$1="AS","consCalcList['","$consCalcList['")&C26&IF($R$1="AS","'] = new logic.C","'] = new C")&MID(C26,2,20)&"();" -> consCalcList['consLIsum'] = new logic.ConsLIsum(); | U26: =IF($R$1="AS","defCons['"&C26&"'] = { "&C$3&":'"&C26&"', "&D$3&": '"&D26&"', "&E$3&":'"&E26&"', "&F$3&":"&F26&", "&G$3&":'"&G26&"', "&H$3&":'"&H26&"', "&I$3&":'"&I26&"', "&J$3&":"&J26&", "&K$3&":'"&K26&"' };","$this->defCons['"&C26&"'] = [ '"&C26&"', '"&D26&"', '"&E26&"', "&F26&", '"&G26&"', '"&H26&"', '"&I26&"', "&J26&", '"&K26&"' ];") -> defCons['consLIsum'] = { name:'consLIsum', nameCode: 'LI', title:'照明', count:0, sumClass:'consTotal', refClass:'', substituteClass:'consSum', code:6, color:'0xffff00' };
B27: 23 | C27: consLI | E27: 照明 | F27: 3 | G27: consLIsum | J27: 6 | L27: 2 | R27: =IF($R$1="AS","consCalcList['","$consCalcList['")&C27&IF($R$1="AS","'] = new logic.C","'] = new C")&MID(C27,2,20)&"();" -> consCalcList['consLI'] = new logic.ConsLI(); | U27: =IF($R$1="AS","defCons['"&C27&"'] = { "&C$3&":'"&C27&"', "&D$3&": '"&D27&"', "&E$3&":'"&E27&"', "&F$3&":"&F27&", "&G$3&":'"&G27&"', "&H$3&":'"&H27&"', "&I$3&":'"&I27&"', "&J$3&":"&J27&", "&K$3&":'"&K27&"' };","$this->defCons['"&C27&"'] = [ '"&C27&"', '"&D27&"', '"&E27&"', "&F27&", '"&G27&"', '"&H27&"', '"&I27&"', "&J27&", '"&K27&"' ];") -> defCons['consLI'] = { name:'consLI', nameCode: '', title:'照明', count:3, sumClass:'consLIsum', refClass:'', substituteClass:'', code:6, color:'' };
B28: 24 | C28: consTVsum | D28: TV | E28: テレビ | F28: 0 | G28: consTotal | I28: consSum | J28: 7 | K28: 0x00ff00 | L28: 1 | R28: =IF($R$1="AS","consCalcList['","$consCalcList['")&C28&IF($R$1="AS","'] = new logic.C","'] = new C")&MID(C28,2,20)&"();" -> consCalcList['consTVsum'] = new logic.ConsTVsum(); | U28: =IF($R$1="AS","defCons['"&C28&"'] = { "&C$3&":'"&C28&"', "&D$3&": '"&D28&"', "&E$3&":'"&E28&"', "&F$3&":"&F28&", "&G$3&":'"&G28&"', "&H$3&":'"&H28&"', "&I$3&":'"&I28&"', "&J$3&":"&J28&", "&K$3&":'"&K28&"' };","$this->defCons['"&C28&"'] = [ '"&C28&"', '"&D28&"', '"&E28&"', "&F28&", '"&G28&"', '"&H28&"', '"&I28&"', "&J28&", '"&K28&"' ];") -> defCons['consTVsum'] = { name:'consTVsum', nameCode: 'TV', title:'テレビ', count:0, sumClass:'consTotal', refClass:'', substituteClass:'consSum', code:7, color:'0x00ff00' };
B29: 25 | C29: consTV | E29: テレビ | F29: 3 | G29: consTVsum | J29: 7 | L29: 3 | R29: =IF($R$1="AS","consCalcList['","$consCalcList['")&C29&IF($R$1="AS","'] = new logic.C","'] = new C")&MID(C29,2,20)&"();" -> consCalcList['consTV'] = new logic.ConsTV(); | U29: =IF($R$1="AS","defCons['"&C29&"'] = { "&C$3&":'"&C29&"', "&D$3&": '"&D29&"', "&E$3&":'"&E29&"', "&F$3&":"&F29&", "&G$3&":'"&G29&"', "&H$3&":'"&H29&"', "&I$3&":'"&I29&"', "&J$3&":"&J29&", "&K$3&":'"&K29&"' };","$this->defCons['"&C29&"'] = [ '"&C29&"', '"&D29&"', '"&E29&"', "&F29&", '"&G29&"', '"&H29&"', '"&I29&"', "&J29&", '"&K29&"' ];") -> defCons['consTV'] = { name:'consTV', nameCode: '', title:'テレビ', count:3, sumClass:'consTVsum', refClass:'', substituteClass:'', code:7, color:'' };
B30: 26 | C30: consCRsum | D30: CR | E30: 交通 | F30: 0 | G30: consTotal | J30: 8 | K30: 0xee82ee | L30: 1 | R30: =IF($R$1="AS","consCalcList['","$consCalcList['")&C30&IF($R$1="AS","'] = new logic.C","'] = new C")&MID(C30,2,20)&"();" -> consCalcList['consCRsum'] = new logic.ConsCRsum(); | U30: =IF($R$1="AS","defCons['"&C30&"'] = { "&C$3&":'"&C30&"', "&D$3&": '"&D30&"', "&E$3&":'"&E30&"', "&F$3&":"&F30&", "&G$3&":'"&G30&"', "&H$3&":'"&H30&"', "&I$3&":'"&I30&"', "&J$3&":"&J30&", "&K$3&":'"&K30&"' };","$this->defCons['"&C30&"'] = [ '"&C30&"', '"&D30&"', '"&E30&"', "&F30&", '"&G30&"', '"&H30&"', '"&I30&"', "&J30&", '"&K30&"' ];") -> defCons['consCRsum'] = { name:'consCRsum', nameCode: 'CR', title:'交通', count:0, sumClass:'consTotal', refClass:'', substituteClass:'', code:8, color:'0xee82ee' };
B31: 27 | C31: consCR | E31: 車 | F31: 3 | G31: consCRsum | H31: consCRtrip | J31: 8 | L31: 3 | R31: =IF($R$1="AS","consCalcList['","$consCalcList['")&C31&IF($R$1="AS","'] = new logic.C","'] = new C")&MID(C31,2,20)&"();" -> consCalcList['consCR'] = new logic.ConsCR(); | U31: =IF($R$1="AS","defCons['"&C31&"'] = { "&C$3&":'"&C31&"', "&D$3&": '"&D31&"', "&E$3&":'"&E31&"', "&F$3&":"&F31&", "&G$3&":'"&G31&"', "&H$3&":'"&H31&"', "&I$3&":'"&I31&"', "&J$3&":"&J31&", "&K$3&":'"&K31&"' };","$this->defCons['"&C31&"'] = [ '"&C31&"', '"&D31&"', '"&E31&"', "&F31&", '"&G31&"', '"&H31&"', '"&I31&"', "&J31&", '"&K31&"' ];") -> defCons['consCR'] = { name:'consCR', nameCode: '', title:'車', count:3, sumClass:'consCRsum', refClass:'consCRtrip', substituteClass:'', code:8, color:'' };
B32: 28 | C32: consCRtrip | E32: 交通 | F32: 5 | G32: consCRsum | H32: consCR | J32: 8 | L32: 2 | R32: =IF($R$1="AS","consCalcList['","$consCalcList['")&C32&IF($R$1="AS","'] = new logic.C","'] = new C")&MID(C32,2,20)&"();" -> consCalcList['consCRtrip'] = new logic.ConsCRtrip(); | U32: =IF($R$1="AS","defCons['"&C32&"'] = { "&C$3&":'"&C32&"', "&D$3&": '"&D32&"', "&E$3&":'"&E32&"', "&F$3&":"&F32&", "&G$3&":'"&G32&"', "&H$3&":'"&H32&"', "&I$3&":'"&I32&"', "&J$3&":"&J32&", "&K$3&":'"&K32&"' };","$this->defCons['"&C32&"'] = [ '"&C32&"', '"&D32&"', '"&E32&"', "&F32&", '"&G32&"', '"&H32&"', '"&I32&"', "&J32&", '"&K32&"' ];") -> defCons['consCRtrip'] = { name:'consCRtrip', nameCode: '', title:'交通', count:5, sumClass:'consCRsum', refClass:'consCR', substituteClass:'', code:8, color:'' };
B33: 29 | C33: consOTsum | D33: OT | E33: 待機・その他 | F33: 0 | G33: consTotal | I33: consSum | J33: 9 | K33: 0xd2691e | L33: 1 | M33: ※積み上げのみ | R33: =IF($R$1="AS","consCalcList['","$consCalcList['")&C33&IF($R$1="AS","'] = new logic.C","'] = new C")&MID(C33,2,20)&"();" -> consCalcList['consOTsum'] = new logic.ConsOTsum(); | U33: =IF($R$1="AS","defCons['"&C33&"'] = { "&C$3&":'"&C33&"', "&D$3&": '"&D33&"', "&E$3&":'"&E33&"', "&F$3&":"&F33&", "&G$3&":'"&G33&"', "&H$3&":'"&H33&"', "&I$3&":'"&I33&"', "&J$3&":"&J33&", "&K$3&":'"&K33&"' };","$this->defCons['"&C33&"'] = [ '"&C33&"', '"&D33&"', '"&E33&"', "&F33&", '"&G33&"', '"&H33&"', '"&I33&"', "&J33&", '"&K33&"' ];") -> defCons['consOTsum'] = { name:'consOTsum', nameCode: 'OT', title:'待機・その他', count:0, sumClass:'consTotal', refClass:'', substituteClass:'consSum', code:9, color:'0xd2691e' };
B34: 30 | C34: consOT | E34: 待機・その他 | F34: 3 | G34: consOTsum | J34: 9 | L34: 3 | R34: =IF($R$1="AS","consCalcList['","$consCalcList['")&C34&IF($R$1="AS","'] = new logic.C","'] = new C")&MID(C34,2,20)&"();" -> consCalcList['consOT'] = new logic.ConsOT(); | U34: =IF($R$1="AS","defCons['"&C34&"'] = { "&C$3&":'"&C34&"', "&D$3&": '"&D34&"', "&E$3&":'"&E34&"', "&F$3&":"&F34&", "&G$3&":'"&G34&"', "&H$3&":'"&H34&"', "&I$3&":'"&I34&"', "&J$3&":"&J34&", "&K$3&":'"&K34&"' };","$this->defCons['"&C34&"'] = [ '"&C34&"', '"&D34&"', '"&E34&"', "&F34&", '"&G34&"', '"&H34&"', '"&I34&"', "&J34&", '"&K34&"' ];") -> defCons['consOT'] = { name:'consOT', nameCode: '', title:'待機・その他', count:3, sumClass:'consOTsum', refClass:'', substituteClass:'', code:9, color:'' };
C37: 暖房が、各部屋の合計にならない場合には、部屋を1つ追加して「その他差分」を設定しておく。
C38: 各機器まで落とすことができるかどうか

Sheet Iems
A1: set in D6/senariofix.js | C1: language set | D1: refernce
A2: =CLEAN(B2&IF(C2="","",""""&C2&""";"))
A3: =CLEAN(B3&IF(C3="","",""""&C3&""";")) -> D6.consAC.title = "部屋空調"; | B3: D6.consAC.title = | C3: 部屋空調 | D3: room air conditioning
A4: =CLEAN(B4&IF(C4="","",""""&C4&""";")) -> D6.consAC.countCall = "部屋目"; | B4: D6.consAC.countCall = | C4: 部屋目 | D4: room
A5: =CLEAN(B5&IF(C5="","",""""&C5&""";"))
A6: =CLEAN(B6&IF(C6="","",""""&C6&""";")) -> D6.consACcool.title = "部屋冷房"; | B6: D6.consACcool.title = | C6: 部屋冷房 | D6: room air conditioning
A7: =CLEAN(B7&IF(C7="","",""""&C7&""";")) -> D6.consACcool.addable = "冷暖房する部屋"; | B7: D6.consACcool.addable = | C7: 冷暖房する部屋 | D7: room air conditioning
A8: =CLEAN(B8&IF(C8="","",""""&C8&""";")) -> D6.consACcool.countCall = "部屋目"; | B8: D6.consACcool.countCall = | C8: 部屋目 | D8: room #
A9: =CLEAN(B9&IF(C9="","",""""&C9&""";")) -> D6.consACcool.inputGuide = "部屋ごとの冷房の使い方について"; | B9: D6.consACcool.inputGuide = | C9: 部屋ごとの冷房の使い方について | D9: how to use air conditioning for each room
A10: =CLEAN(B10&IF(C10="","",""""&C10&""";"))
A11: =CLEAN(B11&IF(C11="","",""""&C11&""";")) -> D6.consACheat.title = "部屋暖房"; | B11: D6.consACheat.title = | C11: 部屋暖房 | D11: room heating
A12: =CLEAN(B12&IF(C12="","",""""&C12&""";")) -> D6.consACheat.addable = "冷暖房する部屋"; | B12: D6.consACheat.addable = | C12: 冷暖房する部屋 | D12: room air conditioning
A13: =CLEAN(B13&IF(C13="","",""""&C13&""";")) -> D6.consACheat.countCall = "部屋目"; | B13: D6.consACheat.countCall = | C13: 部屋目 | D13: room #
A14: =CLEAN(B14&IF(C14="","",""""&C14&""";")) -> D6.consACheat.inputGuide = "部屋ごとの暖房の使い方について"; | B14: D6.consACheat.inputGuide = | C14: 部屋ごとの暖房の使い方について | D14: how to use each room heating
A15: =CLEAN(B15&IF(C15="","",""""&C15&""";"))
A16: =CLEAN(B16&IF(C16="","",""""&C16&""";")) -> D6.consCKcook.title = "調理"; | B16: D6.consCKcook.title = | C16: 調理 | D16: Cooking
A17: =CLEAN(B17&IF(C17="","",""""&C17&""";")) -> D6.consCKcook.inputGuide = "コンロを中心とした調理の使い方について"; | B17: D6.consCKcook.inputGuide = | C17: コンロを中心とした調理の使い方について | D17: How to use cooking to focus on the stove
A18: =CLEAN(B18&IF(C18="","",""""&C18&""";"))
A19: =CLEAN(B19&IF(C19="","",""""&C19&""";")) -> D6.consCKpot.title = "保温"; | B19: D6.consCKpot.title = | C19: 保温 | D19: adiabatic
A20: =CLEAN(B20&IF(C20="","",""""&C20&""";")) -> D6.consCKpot.inputGuide = "保温器具の使い方について"; | B20: D6.consCKpot.inputGuide = | C20: 保温器具の使い方について | D20: How to use insulation
A21: =CLEAN(B21&IF(C21="","",""""&C21&""";"))
A22: =CLEAN(B22&IF(C22="","",""""&C22&""";")) -> D6.consCKrice.title = "炊飯"; | B22: D6.consCKrice.title = | C22: 炊飯 | D22: rice cook
A23: =CLEAN(B23&IF(C23="","",""""&C23&""";")) -> D6.consCKrice.inputGuide = "炊飯の使い方について"; | B23: D6.consCKrice.inputGuide = | C23: 炊飯の使い方について | D23: how to use a rice cooker
A24: =CLEAN(B24&IF(C24="","",""""&C24&""";"))
A25: =CLEAN(B25&IF(C25="","",""""&C25&""";")) -> D6.consCKsum.title = "調理"; | B25: D6.consCKsum.title = | C25: 調理 | D25: Cooking
A26: =CLEAN(B26&IF(C26="","",""""&C26&""";")) -> D6.consCKsum.inputGuide = "調理関連の使い方について"; | B26: D6.consCKsum.inputGuide = | C26: 調理関連の使い方について | D26: How to use cooking related
A27: =CLEAN(B27&IF(C27="","",""""&C27&""";"))
A28: =CLEAN(B28&IF(C28="","",""""&C28&""";")) -> D6.consCOsum.title = "冷房"; | B28: D6.consCOsum.title = | C28: 冷房 | D28: cool
A29: =CLEAN(B29&IF(C29="","",""""&C29&""";")) -> D6.consCOsum.inputGuide = "家全体での冷房の使い方について"; | B29: D6.consCOsum.inputGuide = | C29: 家全体での冷房の使い方について | D29: how to use air conditioning in the whole house
A30: =CLEAN(B30&IF(C30="","",""""&C30&""";"))
A31: =CLEAN(B31&IF(C31="","",""""&C31&""";")) -> D6.consCR.title = "車両"; | B31: D6.consCR.title = | C31: 車両 | D31: vehicle
A32: =CLEAN(B32&IF(C32="","",""""&C32&""";")) -> D6.consCR.addable = "車両"; | B32: D6.consCR.addable = | C32: 車両 | D32: vehicle
A33: =CLEAN(B33&IF(C33="","",""""&C33&""";")) -> D6.consCR.countCall = "台目"; | B33: D6.consCR.countCall = | C33: 台目 | D33: car #
A34: =CLEAN(B34&IF(C34="","",""""&C34&""";")) -> D6.consCR.inputGuide = "保有する車ごとの性能・使い方について"; | B34: D6.consCR.inputGuide = | C34: 保有する車ごとの性能・使い方について | D34: on the performance and use of each car will be held
A35: =CLEAN(B35&IF(C35="","",""""&C35&""";"))
A36: =CLEAN(B36&IF(C36="","",""""&C36&""";")) -> D6.consCRsum.title = "車"; | B36: D6.consCRsum.title = | C36: 車 | D36: vehicle
A37: =CLEAN(B37&IF(C37="","",""""&C37&""";")) -> D6.consCRsum.inputGuide = "車・バイクの使い方について"; | B37: D6.consCRsum.inputGuide = | C37: 車・バイクの使い方について | D37: How to use cars, bicycles
A38: =CLEAN(B38&IF(C38="","",""""&C38&""";"))
A39: =CLEAN(B39&IF(C39="","",""""&C39&""";")) -> D6.consCRtrip.title = "移動"; | B39: D6.consCRtrip.title = | C39: 移動 | D39: movement
A40: =CLEAN(B40&IF(C40="","",""""&C40&""";")) -> D6.consCRtrip.countCall = "ヶ所目"; | B40: D6.consCRtrip.countCall = | C40: ヶ所目 | D40: destination #
...

Sheet Measures
A1: measures definition | D1: Fill cells of this color | X1: for program source code | AD1: 5
B2: mid | C2: name | D2: title | F2: refCons | G2: titleShort | I2: easyness | K2: level | L2: figNum | M2: lifeTime | N2: price | O2: roanShow | P2: standardType | Q2: subsidy | S2: advice | U2: lifestyle | V2: season | AB2: program code in php( not use) | AD2: joyfull
B3: measure ID | C3: code | D3: measure titile(if you want not to show start with # ) | E3: reference(not used) | F3: target consumption | G3: short title | H3: reference | I3: easyness（5easy,1difficult,-1:not show) | J3: refernce | K3: Level(0:always,5:detail only) | L3: picture ID | M3: lifetime(year) | N3: price | O3: use loan | P3: compare to standard type | Q3: subsidy | R3: reference | S3: advice message | T3: reference | U3: lifestylle | V3: season(winter,spring,summer) | Z3: program code in senarioset.js | AB3: $defMeasures = []; | AD3: joyfull advice
B4: 1 | C4: mTOsolar | D4: 太陽光発電を設置する | E4: 太陽光発電を設置する | F4: consTotal | G4: 太陽光発電 | H4: 太陽光発電 | I4: 0.5 | J4: 0.5 | L4: 25 | M4: 20 | N4: 350000 | S4: 発電で余った電気は、FIT制度により電力会社に買い取ってもらうことができ、2025年10月以降に設置した場合は最初の4年間が1kWhあたり24円、5年目から10年目までが8.3円で買取がされます。パネルを設置するだけで発電がされ、モーターなど稼働する部分がないために寿命が長く、維持管理も比較的少なくて済みます。交流に変換をする「コンディショナー」と呼ばれる装置は10年程度ごとに交換が必要になります。<br> また、太陽光発電装置を導入すると、電気を売る様子が表示される装置が設置されます。電気をどれだけ発電できたのか、家庭でどれだけ消費したのかが表示され、機種によっては時間帯別に表示されるものもあります。販売できた金額も表示され、より多く販売するために自然と電気の使用量が減る効果も出てきます。 | T4: 発電で余った電気は、FIT制度により電力会社に買い取ってもらうことができ、2020年度は1kWhあたり21円になります。パネルを設置するだけで発電がされ、モーターなど稼働する部分がないために寿命が長く、維持管理も比較的少なくて済みます。交流に変換をする「コンディショナー」と呼ばれる装置は10年程度ごとに交換が必要になります。<br> また、太陽光発電装置を導入すると、電気を売る様子が表示される装置が設置されます。電気をどれだけ発電できたのか、家庭でどれだけ消費したのかが表示され、機種によっては時間帯別に表示されるものもあります。販売できた金額も表示され、より多く販売するために自然と電気の使用量が減る効果も出てきます。 | V4: wss | Z4: ="D6.scenario.defMeasures['"&C4&"'] = { "&B$2&":"""&B4&""", "&C$2&":"""&C4&""", "&D$2&":"""&CLEAN(SUBSTITUTE(D4,"""","'"))&""", "&I$2&":"""&I4&""", "&F$2&":"""&F4&""", "&G$2&":"""&CLEAN(SUBSTITUTE(G4,"""","'"))&""", "&K$2&":"""&K4&""", "&L$2&":"""&L4&""", "&M$2&":"""&M4&""", "&N$2&":"""&N4&""", "&O$2&":"""&O4&""", "&P$2&":"""&P4&""", "&Q$2&":"""&Q4&""", "&S$2&":"""&CLEAN(SUBSTITUTE(S4,"""","'"))&""", "&U$2&":"""&U4&""", "&V$2&":"""&V4&"""};" -> D6.scenario.defMeasures['mTOsolar'] = { mid:"1", name:"mTOsolar", title:"太陽光発電を設置する", easyness:"0.5", refCons:"consTotal", titleShort:"太陽光発電", level:"", figNum:"25", lifeTime:"20", price:"350000", roanShow:"", standardType:"", subsidy :"", advice:"発電で余った電気は、FIT制度により電力会社に買い取ってもらうことができ、2025年10月以降に設置した場合は最初の4年間が1kWhあたり24円、5年目から10年目までが8.3円で買取がされます。パネルを設置するだけで発電がされ、モーターなど稼働する部分がないために寿命が長く、維持管理も比較的少なくて済みます。交流に変換をする「コンディショナー」と呼ばれる装置は10年程度ごとに交換が必要になります。<br> また、太陽光発電装置を導入すると、電気を売る様子が表示される装置が設置されます。電気をどれだけ発電できたのか、家庭でどれだけ消費したのかが表示され、機種によっては時間帯別に表示されるものもあります。販売できた金額も表示され、より多く販売するために自然と電気の使用量が減る効果も出てきます。", lifestyle:"", season:"wss"}; | AB4: ="$defMeasures['"&C4&"'] = [ '"&B$2&"'=>"""&B4&""", '"&D$2&"'=>"""&CLEAN(SUBSTITUTE(D4,"""","'"))&""", '"&L$2&"'=>"""&L4&""", '"&S$2&"'=>"""&CLEAN(SUBSTITUTE(S4,"""","'"))&"""];" -> $defMeasures['mTOsolar'] = [ 'mid'=>"1", 'title'=>"太陽光発電を設置する", 'figNum'=>"25", 'advice'=>"発電で余った電気は、FIT制度により電力会社に買い取ってもらうことができ、2025年10月以降に設置した場合は最初の4年間が1kWhあたり24円、5年目から10年目までが8.3円で買取がされます。パネルを設置するだけで発電がされ、モーターなど稼働する部分がないために寿命が長く、維持管理も比較的少なくて済みます。交流に変換をする「コンディショナー」と呼ばれる装置は10年程度ごとに交換が必要になります。<br> また、太陽光発電装置を導入すると、電気を売る様子が表示される装置が設置されます。電気をどれだけ発電できたのか、家庭でどれだけ消費したのかが表示され、機種によっては時間帯別に表示されるものもあります。販売できた金額も表示され、より多く販売するために自然と電気の使用量が減る効果も出てきます。"]; | AD4: いくら省エネしても、エネルギーを使わずに生活できるわけはなく、省エネを進めるほど苦しくなるものです。そんな中、自分で「発電する」ことができれば、いともかんたんにゼロが達成できます。いままで電気代を払っていたものが、電気を生産して売れるというのも楽しいですし、それでいて環境にいいことができているわけです。貯金をするよりも利子がつく計算となり、太陽がふりそそぐ屋根をもっていたら、これを逃す手はありません。
B5: 2 | C5: mTOhems | D5: HEMS装置を設置する | E5: HEMS装置を設置する | F5: consTotal | G5: HEMS装置 | H5: HEMS装置 | I5: 1 | J5: 1 | L5: 3 | M5: 20 | N5: 200000 | S5: HEMS(Home Energy Management Sysytem：ヘムス)とは、家庭で使っている電気を時間ごとに細かく把握したり、エアコンなどの家電製品を、省エネのために自動制御したりできるシステムです。電気の使い方などの特徴をチェックすると、どんなことをすれば省エネにつながるか、ポイントが見えてきます。表示されるグラフをもとに、いつ電気の消費が多いのか、何が原因なのか、考えてみてください。 | T5: HEMS(Home Energy Management Sysytem)とは、家庭で使っている電気を時間ごとに細かく把握したり、エアコンなどの家電製品を、省エネのために自動制御したりできるシステムです。電気の使い方などの特徴をチェックすると、どんなことをすれば省エネにつながるか、ポイントが見えてきます。表示されるグラフをもとに、いつ電気の消費が多いのか、何が原因なのか、考えてみてください。 | V5: wss | Z5: ="D6.scenario.defMeasures['"&C5&"'] = { "&B$2&":"""&B5&""", "&C$2&":"""&C5&""", "&D$2&":"""&CLEAN(SUBSTITUTE(D5,"""","'"))&""", "&I$2&":"""&I5&""", "&F$2&":"""&F5&""", "&G$2&":"""&CLEAN(SUBSTITUTE(G5,"""","'"))&""", "&K$2&":"""&K5&""", "&L$2&":"""&L5&""", "&M$2&":"""&M5&""", "&N$2&":"""&N5&""", "&O$2&":"""&O5&""", "&P$2&":"""&P5&""", "&Q$2&":"""&Q5&""", "&S$2&":"""&CLEAN(SUBSTITUTE(S5,"""","'"))&""", "&U$2&":"""&U5&""", "&V$2&":"""&V5&"""};" -> D6.scenario.defMeasures['mTOhems'] = { mid:"2", name:"mTOhems", title:"HEMS装置を設置する", easyness:"1", refCons:"consTotal", titleShort:"HEMS装置", level:"", figNum:"3", lifeTime:"20", price:"200000", roanShow:"", standardType:"", subsidy :"", advice:"HEMS(Home Energy Management Sysytem：ヘムス)とは、家庭で使っている電気を時間ごとに細かく把握したり、エアコンなどの家電製品を、省エネのために自動制御したりできるシステムです。電気の使い方などの特徴をチェックすると、どんなことをすれば省エネにつながるか、ポイントが見えてきます。表示されるグラフをもとに、いつ電気の消費が多いのか、何が原因なのか、考えてみてください。", lifestyle:"", season:"wss"}; | AB5: ="$defMeasures['"&C5&"'] = [ '"&B$2&"'=>"""&B5&""", '"&D$2&"'=>"""&CLEAN(SUBSTITUTE(D5,"""","'"))&""", '"&L$2&"'=>"""&L5&""", '"&S$2&"'=>"""&CLEAN(SUBSTITUTE(S5,"""","'"))&"""];" -> $defMeasures['mTOhems'] = [ 'mid'=>"2", 'title'=>"HEMS装置を設置する", 'figNum'=>"3", 'advice'=>"HEMS(Home Energy Management Sysytem：ヘムス)とは、家庭で使っている電気を時間ごとに細かく把握したり、エアコンなどの家電製品を、省エネのために自動制御したりできるシステムです。電気の使い方などの特徴をチェックすると、どんなことをすれば省エネにつながるか、ポイントが見えてきます。表示されるグラフをもとに、いつ電気の消費が多いのか、何が原因なのか、考えてみてください。"]; | AD5: 家庭の消費状況を見えるだけではなく、家電製品を操作することができるのは大きなポイントです。つけっぱなしだったところを、消しに行くのは面倒ですが、設定によっては自動的に消してくれます。賢い召使がいるような感じでしょうか。
B6: 3 | C6: mTOsolarSmall | D6: ベランダに太陽光パネルを置く | E6: ベランダに太陽光パネルを置く | F6: consTotal | G6: ベランダ太陽光 | H6: ベランダ太陽光 | I6: 2 | J6: 2 | L6: 25 | M6: 10 | N6: 50000 | S6: 太陽光発電パネルを屋根に設置するのではなく、小型のものをベランダなどに置くことで、一部の照明などの用途に使うことができます。既成品として販売されていることもありますが、自分で部品を購入して作ることもできます。太陽光パネル（20～200W）、充放電コントローラー、車用バッテリー、インバーターを組み合わせることで動作し、インターネット通販やホームセンターなどで調達できます。<br> 晴れた日にはふとんを干すような感覚で、日光にあててバッテリーを充電させ、充電された分で活用することができます。曇りの日などは、電気を使うことができない場合があります。 | T6: 太陽光といっても屋根に設置するのではなく、持ち運びできる小型のパネルをベランダなどに置くもので、照明などちょっとした用途に使うことができます。既成品として販売されていることもありますが、自分で作ることもでき、材料は、インターネット通販とホームセンターで調達できます。<br> 晴れた日にはふとんを干すような感覚で、日光にあててバッテリーを充電させ、充電された分で活用することができます。曇りの日などは、電気を使うことができない場合があります。 | V6: wss | Z6: ="D6.scenario.defMeasures['"&C6&"'] = { "&B$2&":"""&B6&""", "&C$2&":"""&C6&""", "&D$2&":"""&CLEAN(SUBSTITUTE(D6,"""","'"))&""", "&I$2&":"""&I6&""", "&F$2&":"""&F6&""", "&G$2&":"""&CLEAN(SUBSTITUTE(G6,"""","'"))&""", "&K$2&":"""&K6&""", "&L$2&":"""&L6&""", "&M$2&":"""&M6&""", "&N$2&":"""&N6&""", "&O$2&":"""&O6&""", "&P$2&":"""&P6&""", "&Q$2&":"""&Q6&""", "&S$2&":"""&CLEAN(SUBSTITUTE(S6,"""","'"))&""", "&U$2&":"""&U6&""", "&V$2&":"""&V6&"""};" -> D6.scenario.defMeasures['mTOsolarSmall'] = { mid:"3", name:"mTOsolarSmall", title:"ベランダに太陽光パネルを置く", easyness:"2", refCons:"consTotal", titleShort:"ベランダ太陽光", level:"", figNum:"25", lifeTime:"10", price:"50000", roanShow:"", standardType:"", subsidy :"", advice:"太陽光発電パネルを屋根に設置するのではなく、小型のものをベランダなどに置くことで、一部の照明などの用途に使うことができます。既成品として販売されていることもありますが、自分で部品を購入して作ることもできます。太陽光パネル（20～200W）、充放電コントローラー、車用バッテリー、インバーターを組み合わせることで動作し、インターネット通販やホームセンターなどで調達できます。<br> 晴れた日にはふとんを干すような感覚で、日光にあててバッテリーを充電させ、充電された分で活用することができます。曇りの日などは、電気を使うことができない場合があります。", lifestyle:"", season:"wss"}; | AB6: ="$defMeasures['"&C6&"'] = [ '"&B$2&"'=>"""&B6&""", '"&D$2&"'=>"""&CLEAN(SUBSTITUTE(D6,"""","'"))&""", '"&L$2&"'=>"""&L6&""", '"&S$2&"'=>"""&CLEAN(SUBSTITUTE(S6,"""","'"))&"""];" -> $defMeasures['mTOsolarSmall'] = [ 'mid'=>"3", 'title'=>"ベランダに太陽光パネルを置く", 'figNum'=>"25", 'advice'=>"太陽光発電パネルを屋根に設置するのではなく、小型のものをベランダなどに置くことで、一部の照明などの用途に使うことができます。既成品として販売されていることもありますが、自分で部品を購入して作ることもできます。太陽光パネル（20～200W）、充放電コントローラー、車用バッテリー、インバーターを組み合わせることで動作し、インターネット通販やホームセンターなどで調達できます。<br> 晴れた日にはふとんを干すような感覚で、日光にあててバッテリーを充電させ、充電された分で活用することができます。曇りの日などは、電気を使うことができない場合があります。"]; | AD6: なんといっても、自分で発電を組み立てることができるのは楽しみです。大型の家電製品は消費電力が大きいので動きませんが、ちょっとした照明くらいなら利用可能です。晴れた日の太陽の恵みをすぐに実感
B7: 6 | C7: mTOzeh | D7: ZEHに建て替える | E7: ZEHに建て替える | F7: consTotal | G7: ZEH | H7: ZEH | I7: 0.5 | J7: 0.5 | L7: 25 | M7: 30 | N7: 22000000 | P7: 省エネ基準住宅 | S7: 断熱性能を高めて省エネ機器設備を導入した上で、太陽光発電を設置すると、家庭のエネルギー消費を実質まかなうことができます。ネット・ゼロ・エネルギー・ハウス（ZEH：ゼッチ）と呼ばれ、すでに大手ハウスメーカーでは新築の標準になっており、2030年頃にはすべての新築住宅でこのレベルを達成することが求められます。エネルギー面でメリットがあるだけでなく、冬は暖かく、夏は涼しく、快適に過ごすことができ、健康面でもメリットがあることがわかっています。 | T7: 発電で余った電気は、FIT制度により電力会社に買い取ってもらうことができ、2020年度は1kWhあたり21円になります。パネルを設置するだけで発電がされ、モーターなど稼働する部分がないために寿命が長く、維持管理も比較的少なくて済みます。交流に変換をする「コンディショナー」と呼ばれる装置は10年程度ごとに交換が必要になります。<br> また、太陽光発電装置を導入すると、電気を売る様子が表示される装置が設置されます。電気をどれだけ発電できたのか、家庭でどれだけ消費したのかが表示され、機種によっては時間帯別に表示されるものもあります。販売できた金額も表示され、より多く販売するために自然と電気の使用量が減る効果も出てきます。 | V7: wss | Z7: ="D6.scenario.defMeasures['"&C7&"'] = { "&B$2&":"""&B7&""", "&C$2&":"""&C7&""", "&D$2&":"""&CLEAN(SUBSTITUTE(D7,"""","'"))&""", "&I$2&":"""&I7&""", "&F$2&":"""&F7&""", "&G$2&":"""&CLEAN(SUBSTITUTE(G7,"""","'"))&""", "&K$2&":"""&K7&""", "&L$2&":"""&L7&""", "&M$2&":"""&M7&""", "&N$2&":"""&N7&""", "&O$2&":"""&O7&""", "&P$2&":"""&P7&""", "&Q$2&":"""&Q7&""", "&S$2&":"""&CLEAN(SUBSTITUTE(S7,"""","'"))&""", "&U$2&":"""&U7&""", "&V$2&":"""&V7&"""};" -> D6.scenario.defMeasures['mTOzeh'] = { mid:"6", name:"mTOzeh", title:"ZEHに建て替える", easyness:"0.5", refCons:"consTotal", titleShort:"ZEH", level:"", figNum:"25", lifeTime:"30", price:"22000000", roanShow:"", standardType:"省エネ基準住宅", subsidy :"", advice:"断熱性能を高めて省エネ機器設備を導入した上で、太陽光発電を設置すると、家庭のエネルギー消費を実質まかなうことができます。ネット・ゼロ・エネルギー・ハウス（ZEH：ゼッチ）と呼ばれ、すでに大手ハウスメーカーでは新築の標準になっており、2030年頃にはすべての新築住宅でこのレベルを達成することが求められます。エネルギー面でメリットがあるだけでなく、冬は暖かく、夏は涼しく、快適に過ごすことができ、健康面でもメリットがあることがわかっています。", lifestyle:"", season:"wss"}; | AB7: ="$defMeasures['"&C7&"'] = [ '"&B$2&"'=>"""&B7&""", '"&D$2&"'=>"""&CLEAN(SUBSTITUTE(D7,"""","'"))&""", '"&L$2&"'=>"""&L7&""", '"&S$2&"'=>"""&CLEAN(SUBSTITUTE(S7,"""","'"))&"""];" -> $defMeasures['mTOzeh'] = [ 'mid'=>"6", 'title'=>"ZEHに建て替える", 'figNum'=>"25", 'advice'=>"断熱性能を高めて省エネ機器設備を導入した上で、太陽光発電を設置すると、家庭のエネルギー消費を実質まかなうことができます。ネット・ゼロ・エネルギー・ハウス（ZEH：ゼッチ）と呼ばれ、すでに大手ハウスメーカーでは新築の標準になっており、2030年頃にはすべての新築住宅でこのレベルを達成することが求められます。エネルギー面でメリットがあるだけでなく、冬は暖かく、夏は涼しく、快適に過ごすことができ、健康面でもメリットがあることがわかっています。"]; | AD7: いくら省エネしても、エネルギーを使わずに生活できるわけはなく、省エネを進めるほど苦しくなるものです。そんな中、自分で「発電する」ことができれば、いともかんたんにゼロが達成できます。いままで電気代を払っていたものが、電気を生産して売れるというのも楽しいですし、それでいて環境にいいことができているわけです。貯金をするよりも利子がつく計算となり、太陽がふりそそぐ屋根をもっていたら、これを逃す手はありません。
B8: 7 | C8: mTObattery | D8: 家庭用蓄電池を設置する | F8: consTotal | G8: 家庭用蓄電池 | I8: 0.5 | J8: 2 | L8: 25 | M8: 10 | N8: 1000000 | S8: 太陽光発電装置で発電がされた電気のうち、使い切れない分を蓄電しておくことで、家庭の電気をより多くまかなうことができます。蓄電池がなくても余った電気を売電することができますが、通常は購入する電気代のほうが高く、その分お得になります。また非常時には蓄電された電気を使って、家電製品を動かすこともにも活用できます。 | V8: wss | Z8: ="D6.scenario.defMeasures['"&C8&"'] = { "&B$2&":"""&B8&""", "&C$2&":"""&C8&""", "&D$2&":"""&CLEAN(SUBSTITUTE(D8,"""","'"))&""", "&I$2&":"""&I8&""", "&F$2&":"""&F8&""", "&G$2&":"""&CLEAN(SUBSTITUTE(G8,"""","'"))&""", "&K$2&":"""&K8&""", "&L$2&":"""&L8&""", "&M$2&":"""&M8&""", "&N$2&":"""&N8&""", "&O$2&":"""&O8&""", "&P$2&":"""&P8&""", "&Q$2&":"""&Q8&""", "&S$2&":"""&CLEAN(SUBSTITUTE(S8,"""","'"))&""", "&U$2&":"""&U8&""", "&V$2&":"""&V8&"""};" -> D6.scenario.defMeasures['mTObattery'] = { mid:"7", name:"mTObattery", title:"家庭用蓄電池を設置する", easyness:"0.5", refCons:"consTotal", titleShort:"家庭用蓄電池", level:"", figNum:"25", lifeTime:"10", price:"1000000", roanShow:"", standardType:"", subsidy :"", advice:"太陽光発電装置で発電がされた電気のうち、使い切れない分を蓄電しておくことで、家庭の電気をより多くまかなうことができます。蓄電池がなくても余った電気を売電することができますが、通常は購入する電気代のほうが高く、その分お得になります。また非常時には蓄電された電気を使って、家電製品を動かすこともにも活用できます。", lifestyle:"", season:"wss"}; | AB8: ="$defMeasures['"&C8&"'] = [ '"&B$2&"'=>"""&B8&""", '"&D$2&"'=>"""&CLEAN(SUBSTITUTE(D8,"""","'"))&""", '"&L$2&"'=>"""&L8&""", '"&S$2&"'=>"""&CLEAN(SUBSTITUTE(S8,"""","'"))&"""];" -> $defMeasures['mTObattery'] = [ 'mid'=>"7", 'title'=>"家庭用蓄電池を設置する", 'figNum'=>"25", 'advice'=>"太陽光発電装置で発電がされた電気のうち、使い切れない分を蓄電しておくことで、家庭の電気をより多くまかなうことができます。蓄電池がなくても余った電気を売電することができますが、通常は購入する電気代のほうが高く、その分お得になります。また非常時には蓄電された電気を使って、家電製品を動かすこともにも活用できます。"]; | AD8: いくら省エネしても、エネルギーを使わずに生活できるわけはなく、省エネを進めるほど苦しくなるものです。そんな中、自分で「発電する」ことができれば、いともかんたんにゼロが達成できます。いままで電気代を払っていたものが、電気を生産して売れるというのも楽しいですし、それでいて環境にいいことができているわけです。貯金をするよりも利子がつく計算となり、太陽がふりそそぐ屋根をもっていたら、これを逃す手はありません。
B9: 8 | C9: mTOv2h | D9: 電気自動車を家庭用蓄電池として活用する | F9: consTotal | G9: V2H | I9: 0.5 | J9: 2 | L9: 21 | M9: 6 | N9: 1000000 | S9: 太陽光発電装置で発電がされた電気のうち、使い切れない分を蓄電しておくことで、家庭の電気をより多くまかなうことができます。蓄電池がなくても余った電気を売電することができますが、通常は購入する電気代のほうが高く、その分お得になります。また非常時には蓄電された電気を使って、家電製品を動かすこともにも活用できます。電気自動車の容量は大きく、連携する装置を購入することで家庭用の蓄電池としても活用することができます。 | V9: wss | Z9: ="D6.scenario.defMeasures['"&C9&"'] = { "&B$2&":"""&B9&""", "&C$2&":"""&C9&""", "&D$2&":"""&CLEAN(SUBSTITUTE(D9,"""","'"))&""", "&I$2&":"""&I9&""", "&F$2&":"""&F9&""", "&G$2&":"""&CLEAN(SUBSTITUTE(G9,"""","'"))&""", "&K$2&":"""&K9&""", "&L$2&":"""&L9&""", "&M$2&":"""&M9&""", "&N$2&":"""&N9&""", "&O$2&":"""&O9&""", "&P$2&":"""&P9&""", "&Q$2&":"""&Q9&""", "&S$2&":"""&CLEAN(SUBSTITUTE(S9,"""","'"))&""", "&U$2&":"""&U9&""", "&V$2&":"""&V9&"""};" -> D6.scenario.defMeasures['mTOv2h'] = { mid:"8", name:"mTOv2h", title:"電気自動車を家庭用蓄電池として活用する", easyness:"0.5", refCons:"consTotal", titleShort:"V2H", level:"", figNum:"21", lifeTime:"6", price:"1000000", roanShow:"", standardType:"", subsidy :"", advice:"太陽光発電装置で発電がされた電気のうち、使い切れない分を蓄電しておくことで、家庭の電気をより多くまかなうことができます。蓄電池がなくても余った電気を売電することができますが、通常は購入する電気代のほうが高く、その分お得になります。また非常時には蓄電された電気を使って、家電製品を動かすこともにも活用できます。電気自動車の容量は大きく、連携する装置を購入することで家庭用の蓄電池としても活用することができます。", lifestyle:"", season:"wss"}; | AB9: ="$defMeasures['"&C9&"'] = [ '"&B$2&"'=>"""&B9&""", '"&D$2&"'=>"""&CLEAN(SUBSTITUTE(D9,"""","'"))&""", '"&L$2&"'=>"""&L9&""", '"&S$2&"'=>"""&CLEAN(SUBSTITUTE(S9,"""","'"))&"""];" -> $defMeasures['mTOv2h'] = [ 'mid'=>"8", 'title'=>"電気自動車を家庭用蓄電池として活用する", 'figNum'=>"21", 'advice'=>"太陽光発電装置で発電がされた電気のうち、使い切れない分を蓄電しておくことで、家庭の電気をより多くまかなうことができます。蓄電池がなくても余った電気を売電することができますが、通常は購入する電気代のほうが高く、その分お得になります。また非常時には蓄電された電気を使って、家電製品を動かすこともにも活用できます。電気自動車の容量は大きく、連携する装置を購入することで家庭用の蓄電池としても活用することができます。"]; | AD9: いくら省エネしても、エネルギーを使わずに生活できるわけはなく、省エネを進めるほど苦しくなるものです。そんな中、自分で「発電する」ことができれば、いともかんたんにゼロが達成できます。いままで電気代を払っていたものが、電気を生産して売れるというのも楽しいですし、それでいて環境にいいことができているわけです。貯金をするよりも利子がつく計算となり、太陽がふりそそぐ屋根をもっていたら、これを逃す手はありません。
B10: 10 | C10: mTOzeroelectricity | D10: CO2排出係数が0の電気を選ぶ | F10: consTotal | G10: 脱炭素電力を選ぶ | I10: 2 | L10: 25 | S10: 電力契約をいろいろな会社から選ぶことができます。一般的な電気ではなく、水力や太陽光発電、風力発電など、CO2排出係数がゼロとなる脱炭素電力のメニューも選べるようになっています。電力会社を変えることで、単価が安くなる場合もあります。 | V10: wss | Z10: ="D6.scenario.defMeasures['"&C10&"'] = { "&B$2&":"""&B10&""", "&C$2&":"""&C10&""", "&D$2&":"""&CLEAN(SUBSTITUTE(D10,"""","'"))&""", "&I$2&":"""&I10&""", "&F$2&":"""&F10&""", "&G$2&":"""&CLEAN(SUBSTITUTE(G10,"""","'"))&""", "&K$2&":"""&K10&""", "&L$2&":"""&L10&""", "&M$2&":"""&M10&""", "&N$2&":"""&N10&""", "&O$2&":"""&O10&""", "&P$2&":"""&P10&""", "&Q$2&":"""&Q10&""", "&S$2&":"""&CLEAN(SUBSTITUTE(S10,"""","'"))&""", "&U$2&":"""&U10&""", "&V$2&":"""&V10&"""};" -> D6.scenario.defMeasures['mTOzeroelectricity'] = { mid:"10", name:"mTOzeroelectricity", title:"CO2排出係数が0の電気を選ぶ", easyness:"2", refCons:"consTotal", titleShort:"脱炭素電力を選ぶ", level:"", figNum:"25", lifeTime:"", price:"", roanShow:"", standardType:"", subsidy :"", advice:"電力契約をいろいろな会社から選ぶことができます。一般的な電気ではなく、水力や太陽光発電、風力発電など、CO2排出係数がゼロとなる脱炭素電力のメニューも選べるようになっています。電力会社を変えることで、単価が安くなる場合もあります。", lifestyle:"", season:"wss"}; | AB10: ="$defMeasures['"&C10&"'] = [ '"&B$2&"'=>"""&B10&""", '"&D$2&"'=>"""&CLEAN(SUBSTITUTE(D10,"""","'"))&""", '"&L$2&"'=>"""&L10&""", '"&S$2&"'=>"""&CLEAN(SUBSTITUTE(S10,"""","'"))&"""];" -> $defMeasures['mTOzeroelectricity'] = [ 'mid'=>"10", 'title'=>"CO2排出係数が0の電気を選ぶ", 'figNum'=>"25", 'advice'=>"電力契約をいろいろな会社から選ぶことができます。一般的な電気ではなく、水力や太陽光発電、風力発電など、CO2排出係数がゼロとなる脱炭素電力のメニューも選べるようになっています。電力会社を変えることで、単価が安くなる場合もあります。"]; | AD10: いくら省エネしても、エネルギーを使わずに生活できるわけはなく、省エネを進めるほど苦しくなるものです。そんな中、自分で「発電する」ことができれば、いともかんたんにゼロが達成できます。いままで電気代を払っていたものが、電気を生産して売れるというのも楽しいですし、それでいて環境にいいことができているわけです。貯金をするよりも利子がつく計算となり、太陽がふりそそぐ屋根をもっていたら、これを逃す手はありません。
B11: 101 | C11: mHWecocute | D11: 給湯器をエコキュートに買い換える | E11: 給湯器をエコキュートに買い換える | F11: consHWsum | G11: エコキュート | H11: エコキュート | I11: 2 | J11: 2 | L11: 8 | M11: 10 | N11: 400000 | O11: 1 | P11: 電気温水器 | Q11: 子育てグリーン住宅支援事業の対象で、他の断熱工事や機器導入を行って補助額が5万円以上になると補助されます。 | S11: エコキュート(R)（自然冷媒ヒートポンプ給湯器）は、エアコンの室外機のような装置がついており、外気の熱を利用してお湯を沸かすため、電気温水器より3倍以上効率がよくなります。貯湯槽にためたお湯を使い切るような、家族人数が多く、毎日欠かさずお風呂に入る家庭にはお勧めです。<br> また、ふだんのお湯の使い方を考慮して控えめに沸かす設定をすると、さらに省エネにつながります。 | T11: エコキュート(R)（自然冷媒ヒートポンプ給湯器）は、エアコンの室外機のような装置がついており、外気の熱を利用してお湯を沸かすため、電気温水器より3倍以上効率がよくなります。貯湯槽にためたお湯を使い切るような、家族人数が多く、毎日欠かさずお風呂に入る家庭にはお勧めです。<br> また、ふだんのお湯の使い方を考慮して控えめに沸かす設定をすると、さらに省エネにつながります。 | V11: wss | Z11: ="D6.scenario.defMeasures['"&C11&"'] = { "&B$2&":"""&B11&""", "&C$2&":"""&C11&""", "&D$2&":"""&CLEAN(SUBSTITUTE(D11,"""","'"))&""", "&I$2&":"""&I11&""", "&F$2&":"""&F11&""", "&G$2&":"""&CLEAN(SUBSTITUTE(G11,"""","'"))&""", "&K$2&":"""&K11&""", "&L$2&":"""&L11&""", "&M$2&":"""&M11&""", "&N$2&":"""&N11&""", "&O$2&":"""&O11&""", "&P$2&":"""&P11&""", "&Q$2&":"""&Q11&""", "&S$2&":"""&CLEAN(SUBSTITUTE(S11,"""","'"))&""", "&U$2&":"""&U11&""", "&V$2&":"""&V11&"""};" -> D6.scenario.defMeasures['mHWecocute'] = { mid:"101", name:"mHWecocute", title:"給湯器をエコキュートに買い換える", easyness:"2", refCons:"consHWsum", titleShort:"エコキュート", level:"", figNum:"8", lifeTime:"10", price:"400000", roanShow:"1", standardType:"電気温水器", subsidy :"子育てグリーン住宅支援事業の対象で、他の断熱工事や機器導入を行って補助額が5万円以上になると補助されます。", advice:"エコキュート(R)（自然冷媒ヒートポンプ給湯器）は、エアコンの室外機のような装置がついており、外気の熱を利用してお湯を沸かすため、電気温水器より3倍以上効率がよくなります。貯湯槽にためたお湯を使い切るような、家族人数が多く、毎日欠かさずお風呂に入る家庭にはお勧めです。<br> また、ふだんのお湯の使い方を考慮して控えめに沸かす設定をすると、さらに省エネにつながります。", lifestyle:"", season:"wss"}; | AB11: ="$defMeasures['"&C11&"'] = [ '"&B$2&"'=>"""&B11&""", '"&D$2&"'=>"""&CLEAN(SUBSTITUTE(D11,"""","'"))&""", '"&L$2&"'=>"""&L11&""", '"&S$2&"'=>"""&CLEAN(SUBSTITUTE(S11,"""","'"))&"""];" -> $defMeasures['mHWecocute'] = [ 'mid'=>"101", 'title'=>"給湯器をエコキュートに買い換える", 'figNum'=>"8", 'advice'=>"エコキュート(R)（自然冷媒ヒートポンプ給湯器）は、エアコンの室外機のような装置がついており、外気の熱を利用してお湯を沸かすため、電気温水器より3倍以上効率がよくなります。貯湯槽にためたお湯を使い切るような、家族人数が多く、毎日欠かさずお風呂に入る家庭にはお勧めです。<br> また、ふだんのお湯の使い方を考慮して控えめに沸かす設定をすると、さらに省エネにつながります。"]; | AD11: 外気の熱を使ってお湯をわかすために、電気の消費は大幅に減ります。ただ貯湯槽の大きさが限られているので、大量にお湯を使う家庭や、盆や正月で人数が急に増えた場合には、湯切れを起こすこともあります。湯切れを起こさないようにと、限られたお湯を大切に使うことも、省エネの基本的な視点です。
B12: 102 | C12: mHWecojoze | D12: 給湯器をエコジョーズ（潜熱回収型ガス給湯器）に買い換える | E12: 給湯器をエコジョーズ（潜熱回収型）に買い換える | F12: consHWsum | G12: エコジョーズ | H12: エコジョーズ | I12: 2 | J12: 2 | L12: 10 | M12: 10 | N12: 200000 | P12: 既存型 | Q12: 子育てグリーン住宅支援事業の対象で、他の断熱工事や機器導入を行って補助額が5万円以上になると補助されます。 | S12: エコジョーズ(R)（潜熱回収型）は、水蒸気として逃げていた熱も回収する仕組みのため、既存のガス給湯器に比べて効率が1割以上向上しています。既存のガス給湯器とほぼ同じ形で置き換えが可能です。熱を回収する際に発生する水を流すドレンがついており、マンションなど排水口が近くにない場合には、工事が必要となる場合があります。ガス会社によってはエコジョーズ料金により、ガス代が割り引かれる場合もあります。 | T12: エコジョーズ(R)（潜熱回収型）は、水蒸気として逃げていた熱も回収する仕組みのため、既存のガス給湯器に比べて効率が1割以上向上しています。既存のガス給湯器とほぼ同じ形ですが、熱回収をするために少し大型になっており、また熱を回収する際に発生する水を流すドレンもついています。ガス会社によってはエコジョーズ料金により、ガス代が割り引かれる場合もあります。 | V12: wss | Z12: ="D6.scenario.defMeasures['"&C12&"'] = { "&B$2&":"""&B12&""", "&C$2&":"""&C12&""", "&D$2&":"""&CLEAN(SUBSTITUTE(D12,"""","'"))&""", "&I$2&":"""&I12&""", "&F$2&":"""&F12&""", "&G$2&":"""&CLEAN(SUBSTITUTE(G12,"""","'"))&""", "&K$2&":"""&K12&""", "&L$2&":"""&L12&""", "&M$2&":"""&M12&""", "&N$2&":"""&N12&""", "&O$2&":"""&O12&""", "&P$2&":"""&P12&""", "&Q$2&":"""&Q12&""", "&S$2&":"""&CLEAN(SUBSTITUTE(S12,"""","'"))&""", "&U$2&":"""&U12&""", "&V$2&":"""&V12&"""};" -> D6.scenario.defMeasures['mHWecojoze'] = { mid:"102", name:"mHWecojoze", title:"給湯器をエコジョーズ（潜熱回収型ガス給湯器）に買い換える", easyness:"2", refCons:"consHWsum", titleShort:"エコジョーズ", level:"", figNum:"10", lifeTime:"10", price:"200000", roanShow:"", standardType:"既存型", subsidy :"子育てグリーン住宅支援事業の対象で、他の断熱工事や機器導入を行って補助額が5万円以上になると補助されます。", advice:"エコジョーズ(R)（潜熱回収型）は、水蒸気として逃げていた熱も回収する仕組みのため、既存のガス給湯器に比べて効率が1割以上向上しています。既存のガス給湯器とほぼ同じ形で置き換えが可能です。熱を回収する際に発生する水を流すドレンがついており、マンションなど排水口が近くにない場合には、工事が必要となる場合があります。ガス会社によってはエコジョーズ料金により、ガス代が割り引かれる場合もあります。", lifestyle:"", season:"wss"}; | AB12: ="$defMeasures['"&C12&"'] = [ '"&B$2&"'=>"""&B12&""", '"&D$2&"'=>"""&CLEAN(SUBSTITUTE(D12,"""","'"))&""", '"&L$2&"'=>"""&L12&""", '"&S$2&"'=>"""&CLEAN(SUBSTITUTE(S12,"""","'"))&"""];" -> $defMeasures['mHWecojoze'] = [ 'mid'=>"102", 'title'=>"給湯器をエコジョーズ（潜熱回収型ガス給湯器）に買い換える", 'figNum'=>"10", 'advice'=>"エコジョーズ(R)（潜熱回収型）は、水蒸気として逃げていた熱も回収する仕組みのため、既存のガス給湯器に比べて効率が1割以上向上しています。既存のガス給湯器とほぼ同じ形で置き換えが可能です。熱を回収する際に発生する水を流すドレンがついており、マンションなど排水口が近くにない場合には、工事が必要となる場合があります。ガス会社によってはエコジョーズ料金により、ガス代が割り引かれる場合もあります。"]; | AD12: エコジョーズなど新しい給湯器は、省エネ性能が高いだけでなく、細かい制御ができるように改良されているため、お湯の温度変化も小さく、快適です。ガス代としても、給湯にかかる分が1割程度減りますので、金銭的にもお得になります。
B13: 103 | C13: mHWecofeel | D13: 給湯器をエコフィール（潜熱回収型灯油給湯器）に買い換える | E13: 給湯器をエコフィール（潜熱回収型）に買い換える | F13: consHWsum | G13: エコフィール | H13: エコフィール | I13: 1 | J13: 1 | L13: 10 | M13: 10 | N13: 250000 | P13: 既存型 | Q13: 子育てグリーン住宅支援事業の対象で、他の断熱工事や機器導入を行って補助額が5万円以上になると補助されます。 | S13: エコフィール(R)（潜熱回収型）は、水蒸気として逃げていた熱も回収する仕組みのため、効率が1割以上向上しています。既存の灯油ボイラーとほぼ同じ形で、交換ができます。灯油ではなくガスのタイプは「エコジョース」といいます。 | T13: エコフィール(R)（潜熱回収型）は、水蒸気として逃げていた熱も回収する仕組みのため、効率が1割以上向上しています。既存の灯油ボイラーとほぼ同じ形ですが、熱回収をするために少し大型になっており、また熱を回収する際に発生する水を流すドレンもついています。灯油ではなくガスのタイプは「エコジョース」といいます。 | V13: wss | Z13: ="D6.scenario.defMeasures['"&C13&"'] = { "&B$2&":"""&B13&""", "&C$2&":"""&C13&""", "&D$2&":"""&CLEAN(SUBSTITUTE(D13,"""","'"))&""", "&I$2&":"""&I13&""", "&F$2&":"""&F13&""", "&G$2&":"""&CLEAN(SUBSTITUTE(G13,"""","'"))&""", "&K$2&":"""&K13&""", "&L$2&":"""&L13&""", "&M$2&":"""&M13&""", "&N$2&":"""&N13&""", "&O$2&":"""&O13&""", "&P$2&":"""&P13&""", "&Q$2&":"""&Q13&""", "&S$2&":"""&CLEAN(SUBSTITUTE(S13,"""","'"))&""", "&U$2&":"""&U13&""", "&V$2&":"""&V13&"""};" -> D6.scenario.defMeasures['mHWecofeel'] = { mid:"103", name:"mHWecofeel", title:"給湯器をエコフィール（潜熱回収型灯油給湯器）に買い換える", easyness:"1", refCons:"consHWsum", titleShort:"エコフィール", level:"", figNum:"10", lifeTime:"10", price:"250000", roanShow:"", standardType:"既存型", subsidy :"子育てグリーン住宅支援事業の対象で、他の断熱工事や機器導入を行って補助額が5万円以上になると補助されます。", advice:"エコフィール(R)（潜熱回収型）は、水蒸気として逃げていた熱も回収する仕組みのため、効率が1割以上向上しています。既存の灯油ボイラーとほぼ同じ形で、交換ができます。灯油ではなくガスのタイプは「エコジョース」といいます。", lifestyle:"", season:"wss"}; | AB13: ="$defMeasures['"&C13&"'] = [ '"&B$2&"'=>"""&B13&""", '"&D$2&"'=>"""&CLEAN(SUBSTITUTE(D13,"""","'"))&""", '"&L$2&"'=>"""&L13&""", '"&S$2&"'=>"""&CLEAN(SUBSTITUTE(S13,"""","'"))&"""];" -> $defMeasures['mHWecofeel'] = [ 'mid'=>"103", 'title'=>"給湯器をエコフィール（潜熱回収型灯油給湯器）に買い換える", 'figNum'=>"10", 'advice'=>"エコフィール(R)（潜熱回収型）は、水蒸気として逃げていた熱も回収する仕組みのため、効率が1割以上向上しています。既存の灯油ボイラーとほぼ同じ形で、交換ができます。灯油ではなくガスのタイプは「エコジョース」といいます。"]; | AD13: 灯油を燃料とする高効率給湯としては、エコフィールが唯一です。従来型のボイラーとくらべて、熱のロスを3分の1以下にしています。おおよそ1割減るので、灯油代を比較してみると、成果がみえてくるかもしれません。
B14: 104 | C14: mHWenefarmSOFC | D14: 給湯器をSOFCタイプのエネファーム（燃料電池）に買い換える | E14: 給湯器をエネファーム（燃料電池）に買い換える | F14: consHWsum | G14: エネファームSOFC | H14: エネファーム | I14: 0.5 | J14: 0.5 | K14: 5 | L14: 10 | M14: 10 | N14: 1100000 | O14: 1 | P14: エコジョーズ | S14: エネファーム(R)は、燃料電池で発電をしながらお湯をわかす効率がよい装置です。家庭で消費する電気の分だけ発電を行い、発生した余熱をお湯としてためて利用することができます。電気やお湯をたくさん使う家庭で、大きな省エネ効果が期待できます。SOFCタイプは、さらに発電効率が高くなってり、お湯の発生量が少ないため、比較的お湯を使わない家庭でも効果がでます。発電を行うため、停電時にも一定の電気を取り出すことが可能となっています。 | T14: エネファーム(R)は、燃料電池で発電をしながらお湯をわかす効率がよい装置です。家庭で消費する電気の分だけ発電を行い、発生した余熱をお湯としてためて利用することができます。電気やお湯をたくさん使う家庭で、大きな省エネ効果が期待できます。SOFCタイプは、さらに発電効率が高くなってり、お湯の発生量が少ないため、比較的お湯を使わない家庭でも効果がでます。発電を行うため、停電時にも一定の電気を取り出すことが可能となっています。 | V14: wss | Z14: ="D6.scenario.defMeasures['"&C14&"'] = { "&B$2&":"""&B14&""", "&C$2&":"""&C14&""", "&D$2&":"""&CLEAN(SUBSTITUTE(D14,"""","'"))&""", "&I$2&":"""&I14&""", "&F$2&":"""&F14&""", "&G$2&":"""&CLEAN(SUBSTITUTE(G14,"""","'"))&""", "&K$2&":"""&K14&""", "&L$2&":"""&L14&""", "&M$2&":"""&M14&""", "&N$2&":"""&N14&""", "&O$2&":"""&O14&""", "&P$2&":"""&P14&""", "&Q$2&":"""&Q14&""", "&S$2&":"""&CLEAN(SUBSTITUTE(S14,"""","'"))&""", "&U$2&":"""&U14&""", "&V$2&":"""&V14&"""};" -> D6.scenario.defMeasures['mHWenefarmSOFC'] = { mid:"104", name:"mHWenefarmSOFC", title:"給湯器をSOFCタイプのエネファーム（燃料電池）に買い換える", easyness:"0.5", refCons:"consHWsum", titleShort:"エネファームSOFC", level:"5", figNum:"10", lifeTime:"10", price:"1100000", roanShow:"1", standardType:"エコジョーズ", subsidy :"", advice:"エネファーム(R)は、燃料電池で発電をしながらお湯をわかす効率がよい装置です。家庭で消費する電気の分だけ発電を行い、発生した余熱をお湯としてためて利用することができます。電気やお湯をたくさん使う家庭で、大きな省エネ効果が期待できます。SOFCタイプは、さらに発電効率が高くなってり、お湯の発生量が少ないため、比較的お湯を使わない家庭でも効果がでます。発電を行うため、停電時にも一定の電気を取り出すことが可能となっています。", lifestyle:"", season:"wss"}; | AB14: ="$defMeasures['"&C14&"'] = [ '"&B$2&"'=>"""&B14&""", '"&D$2&"'=>"""&CLEAN(SUBSTITUTE(D14,"""","'"))&""", '"&L$2&"'=>"""&L14&""", '"&S$2&"'=>"""&CLEAN(SUBSTITUTE(S14,"""","'"))&"""];" -> $defMeasures['mHWenefarmSOFC'] = [ 'mid'=>"104", 'title'=>"給湯器をSOFCタイプのエネファーム（燃料電池）に買い換える", 'figNum'=>"10", 'advice'=>"エネファーム(R)は、燃料電池で発電をしながらお湯をわかす効率がよい装置です。家庭で消費する電気の分だけ発電を行い、発生した余熱をお湯としてためて利用することができます。電気やお湯をたくさん使う家庭で、大きな省エネ効果が期待できます。SOFCタイプは、さらに発電効率が高くなってり、お湯の発生量が少ないため、比較的お湯を使わない家庭でも効果がでます。発電を行うため、停電時にも一定の電気を取り出すことが可能となっています。"]; | AD14: 夢の技術とされた燃料電池が、実用的に広まりつつあります。停電時にも、発電して電気を生み出し使えるというのは、大きなメリットです。
